Workbook

Sheet Document control
A1: EM26-19 — Deliverable Review Feedback and Action Log (2025 → 2026)
A2: AJACE Inc. · EchoMind Product · ISO 9001:2015 evidence · Controlled in docs/qms (git); uncontrolled when printed
A4: Field | B4: Entry
A5: Document ID | B5: EM26-19
A6: Title | B6: Deliverable Review Feedback and Action Log (2025 → 2026)
A7: Version | B7: 1.1
A8: Date | B8: 2026-10-12
A9: Organisation | B9: AJACE Inc. — 14159 Robert Paris Ct., Suite A, Chantilly, VA 20151, USA
A10: Area / project | B10: EchoMind Product — EchoMind (2025 pilot appliance) and EchoMind Enterprise (2026, repository RW2523/echomind-enterprise)
A11: Status | B11: APPROVED — rev 1.1 2026-10-12 (AR-2026-004); rev 1.0 2026-10-12 (AR-2026-003)
A12: Purpose | B12: Every review of an EchoMind deliverable from May 2025 to October 2026 — by clients, the Project Lead, engineering and auditors — with its feedback, decision, the actions raised, their owners, due dates and closure evidence; and the two-monthly review cycle.
A13: Sources | B13: 2025: minutes MM-ECHO-2025-05/07/09; Deliverables, Scheduling and Acceptance Criteria Review records (DR-1.0, SCH-1.0, ACC-1.0); SOW; internal audit 2025-09-24; Stage 2 audit 2025-10-16. 2026: git history, REG-10, EM26-18, REG-04, test runs.
A14: Copy | B14: PUBLIC COPY — clients shown as Client A–D; the controlled copy given to the auditor carries the names
A15: Dating rule | B15: Every date comes from a record: a 2025 minute or review document, a git commit, a register entry or a test run. Where a remembered month and the commit record differed, the commit date is used. Nothing is back-dated.
... A22: Summary | B22: Reviews and actions by year and by source (live formulas)
A24: Role | B24: Name | C24: Signature | D24: Date
A25: Prepared by — Lead Engineer | B25: Richard Watson Stephen Amudha | C25: Richard Watson Stephen Amudha | D25: 2026-10-12
A26: Reviewed by — EchoMind Project Lead | B26: Alexander Peter | C26: Alexander Peter | D26: 2026-10-12
A27: Quality assurance — QA / MR | B27: Sheryl Nazareth | C27: Sheryl Nazareth | D27: 2026-10-12
A28: Approved by — Managing Director | B28: Anita Johan | C28: Anita Johan | D28: 2026-10-12
A30: Approval record
A31: Rev 1.1: docs/qms/records/approvals/2026-10-12_AR-2026-004_register_revision_approval.md; rev 1.0: …/2026-10-12_AR-2026-003_register_approval.md. Review and approval confirmed by each role holder; signatures are their typed names (SOP-01 §6).
A33: Date | B33: Version | C33: Owner | D33: Change
A34: 2026-10-11 | B34: 1.0 | C34: Richard Watson Stephen Amudha (Lead Engineer) | D34: First issue
A35: 2026-10-12 | B35: 1.0 | C35: Anita Johan (Managing Director) | D35: Approved — AR-2026-003
A36: 2026-10-12 | B36: 1.1 | C36: Richard Watson Stephen Amudha (Lead Engineer) | D36: Versions v1.0.0–v1.4.1 added (v1.0.0–v1.3.0 retrospective baselines, REG-08 §2a); version reviews
A37: 2026-10-12 | B37: 1.1 | C37: Anita Johan (Managing Director) | D37: Approved — AR-2026-004

Sheet Review cycle
A1: Review cycle — every two months, May 2025 → October 2026
A2: Counts are live formulas over the Review log and Action log sheets.
A4: Period | B4: Window | C4: Product state / version | D4: Commits on main | E4: Reviews held | F4: Reviews | G4: Actions raised | H4: Actions closed | I4: Review status
A5: P-2025-1 | B5: May–Jun 2025 | C5: 2025 appliance — architecture, requirements and prototype plan | D5: n/a (2025 repositories) | E5: DR-2025-01, DR-2025-02, DR-2025-03, DR-2025-04 | F5: =COUNTIF('Review log'!$C:$C,A5) | G5: =SUMIF('Action log'!$C:$C,A5,'Action log'!$K:$K) | H5: =SUMIFS('Action log'!$K:$K,'Action log'!$C:$C,A5,'Action log'!$F:$F,"Closed*") | I5: Held
A6: P-2025-2 | B6: Jul–Aug 2025 | C6: 2025 appliance — prototype hardware, QA sprint, SOW signed | D6: n/a (2025 repositories) | E6: DR-2025-05, DR-2025-06, DR-2025-07, DR-2025-08, DR-2025-09, DR-2025-10 | F6: =COUNTIF('Review log'!$C:$C,A6) | G6: =SUMIF('Action log'!$C:$C,A6,'Action log'!$K:$K) | H6: =SUMIFS('Action log'!$K:$K,'Action log'!$C:$C,A6,'Action log'!$F:$F,"Closed*") | I6: Held
A7: P-2025-3 | B7: Sep–Oct 2025 | C7: 2025 appliance — final release package delivered; internal audit; Stage 2 certification audit | D7: n/a (2025 repositories) | E7: DR-2025-11, DR-2025-12, DR-2025-13, DR-2025-14, DR-2025-15 | F7: =COUNTIF('Review log'!$C:$C,A7) | G7: =SUMIF('Action log'!$C:$C,A7,'Action log'!$K:$K) | H7: =SUMIFS('Action log'!$K:$K,'Action log'!$C:$C,A7,'Action log'!$F:$F,"Closed*") | I7: Held
A8: P-2025-4 | B8: Nov–Dec 2025 | C8: No product release (2025 project closed; next platform under evaluation) | D8: n/a (2025 repositories) | E8: None — no deliverable in the period | F8: =COUNTIF('Review log'!$C:$C,A8) | G8: =SUMIF('Action log'!$C:$C,A8,'Action log'!$K:$K) | H8: =SUMIFS('Action log'!$K:$K,'Action log'!$C:$C,A8,'Action log'!$F:$F,"Closed*") | I8: No review needed — no deliverable
A9: P-2026-1 | B9: Jan–Feb 2026 | C9: v1.0.0 — platform decision; 2025 code ported to the DGX Spark | D9: 84 | E9: CR-2026-01 | F9: =COUNTIF('Review log'!$C:$C,A9) | G9: =SUMIF('Action log'!$C:$C,A9,'Action log'!$K:$K) | H9: =SUMIFS('Action log'!$K:$K,'Action log'!$C:$C,A9,'Action log'!$F:$F,"Closed*") | I9: Held
A10: P-2026-2 | B10: Mar–Apr 2026 | C10: v1.1.0 — DoD FMR knowledge base; conversation v1 → v2 → own dual loop; TensorRT-LLM; Nemotron speech; hotspot | D10: 32 | E10: CR-2026-02, CR-2026-03, CR-2026-04, CR-2026-05, CR-2026-06 | F10: =COUNTIF('Review log'!$C:$C,A10) | G10: =SUMIF('Action log'!$C:$C,A10,'Action log'!$K:$K) | H10: =SUMIFS('Action log'!$K:$K,'Action log'!$C:$C,A10,'Action log'!$F:$F,"Closed*") | I10: Held
A11: P-2026-3 | B11: May–Jun 2026 | C11: v1.2.0 — Silent Assistant, Boardroom, Document Studio, login and roles, vertical packs, public reference instance | D11: 44 | E11: CR-2026-07, CR-2026-08, CR-2026-09, SR-2026-01 | F11: =COUNTIF('Review log'!$C:$C,A11) | G11: =SUMIF('Action log'!$C:$C,A11,'Action log'!$K:$K) | H11: =SUMIFS('Action log'!$K:$K,'Action log'!$C:$C,A11,'Action log'!$F:$F,"Closed*") | I11: Held
A12: P-2026-4 | B12: Jul–Aug 2026 | C12: v1.3.0 — TensorRT-LLM NVFP4 in production, golden evaluation, RAG overhaul, QASC 2026 paper | D12: 39 | E12: RV-2026-01, RV-2026-02 | F12: =COUNTIF('Review log'!$C:$C,A12) | G12: =SUMIF('Action log'!$C:$C,A12,'Action log'!$K:$K) | H12: =SUMIFS('Action log'!$K:$K,'Action log'!$C:$C,A12,'Action log'!$F:$F,"Closed*") | I12: Held
A13: P-2026-5 | B13: Sep–Oct 2026 | C13: v1.4.0 (2026-09-22) and v1.4.1 (2026-10-06) — released with release records; QMS approved | D13: 43 | E13: RV-2026-03, RV-2026-04, RV-2026-05, RV-2026-06, RV-2026-07, RV-2026-08 | F13: =COUNTIF('Review log'!$C:$C,A13) | G13: =SUMIF('Action log'!$C:$C,A13,'Action log'!$K:$K) | H13: =SUMIFS('Action log'!$K:$K,'Action log'!$C:$C,A13,'Action log'!$F:$F,"Closed*") | I13: Held

Sheet Version reviews
A1: Version reviews — v1.0.0 → v1.4.1 (2026)
A2: v1.0.0–v1.3.0 are retrospective baselines tagged on 2026-10-12 on the last commit of each increment; v1.4.0 and v1.4.1 are releases with release records (REG-08). Counts are live formulas.
A4: Version | B4: Type | C4: Date | D4: Commit | E4: Window | F4: Scope (from the commits) | G4: Version reviews | H4: Reviews | I4: Actions raised | J4: Actions closed | K4: Review status
A5: v1.0.0 | B5: Retrospective baseline | C5: 2026-02-27 | D5: 595b24b | E5: Jan–Feb 2026 | F5: 2025 code ported to the DGX Spark; knowledge chat with citations; live transcription; Kyutai speech; voice with barge-in; wake word and listen-only | G5: CR-2026-01, CR-2026-02, CR-2026-03 | H5: =COUNTIF('Review log'!$O:$O,A5) | I5: =SUMIF('Action log'!$L:$L,A5,'Action log'!$K:$K) | J5: =SUMIFS('Action log'!$K:$K,'Action log'!$L:$L,A5,'Action log'!$F:$F,"Closed*") | K5: Held
A6: v1.1.0 | B6: Retrospective baseline | C6: 2026-04-29 | D6: e5292f3 | E6: Mar–Apr 2026 | F6: DoD FMR knowledge base (section and TOC retrieval); financial assistant; TensorRT-LLM integrated; own dual-loop voice; Nemotron speech; personas; offline preparation | G6: CR-2026-04, CR-2026-05, CR-2026-06, CR-2026-07 | H6: =COUNTIF('Review log'!$O:$O,A6) | I6: =SUMIF('Action log'!$L:$L,A6,'Action log'!$K:$K) | J6: =SUMIFS('Action log'!$K:$K,'Action log'!$L:$L,A6,'Action log'!$F:$F,"Closed*") | K6: Held
A7: v1.2.0 | B7: Retrospective baseline | C7: 2026-06-27 | D7: 46bd774 | E7: May–Jun 2026 | F7: Silent Assistant; Boardroom; code-audit fixes; Document Studio; Parakeet final STT; login, roles, tenancy, export gateway; vertical packs; public reference instance | G7: CR-2026-08, SR-2026-01, CR-2026-09 | H7: =COUNTIF('Review log'!$O:$O,A7) | I7: =SUMIF('Action log'!$L:$L,A7,'Action log'!$K:$K) | J7: =SUMIFS('Action log'!$K:$K,'Action log'!$L:$L,A7,'Action log'!$F:$F,"Closed*") | K7: Held
A8: v1.3.0 | B8: Retrospective baseline | C8: 2026-08-16 | D8: bc9aa33 | E8: Jul–Aug 2026 | F8: TensorRT-LLM NVFP4 in production; golden evaluation; retrieval fixes; RAG ingestion overhaul; Silent Assistant v2; QASC 2026 results | G8: RV-2026-01, RV-2026-02 | H8: =COUNTIF('Review log'!$O:$O,A8) | I8: =SUMIF('Action log'!$L:$L,A8,'Action log'!$K:$K) | J8: =SUMIFS('Action log'!$K:$K,'Action log'!$L:$L,A8,'Action log'!$F:$F,"Closed*") | K8: Held
A9: v1.4.0 | B9: Release (FRM-03) | C9: 2026-09-22 | D9: eaa7b1a | E9: Sep 2026 | F9: Voice redesign (speculative replies, tool routing); release identification; backup and restore; QMS documentation | G9: RV-2026-03, RV-2026-04, RV-2026-05, RV-2026-06 | H9: =COUNTIF('Review log'!$O:$O,A9) | I9: =SUMIF('Action log'!$L:$L,A9,'Action log'!$K:$K) | J9: =SUMIFS('Action log'!$K:$K,'Action log'!$L:$L,A9,'Action log'!$F:$F,"Closed*") | K9: Held
A10: v1.4.1 | B10: Release (FRM-03) | C10: 2026-10-06 | D10: f1b8445 | E10: Oct 2026 | F10: Defect fixes from acceptance testing; CI; external login check; CPU fallback for speech and embeddings | G10: RV-2026-07, RV-2026-08 | H10: =COUNTIF('Review log'!$O:$O,A10) | I10: =SUMIF('Action log'!$L:$L,A10,'Action log'!$K:$K) | J10: =SUMIFS('Action log'!$K:$K,'Action log'!$L:$L,A10,'Action log'!$F:$F,"Closed*") | K10: Held

Sheet Review log
A1: Review log — 2025 → 2026
A2: Every review is backed by a record (minute, review document, audit report, commit or test run).
A4: Review ID | B4: Date | C4: Period | D4: Product / version reviewed | E4: Deliverable | F4: Review type | G4: Source | H4: Reviewed by | I4: Feedback / findings | J4: Decision / outcome | K4: Record / evidence | L4: Actions | M4: Closed | N4: Open | O4: Version
A5: DR-2025-01 | B5: 2025-05-15 | C5: P-2025-1 | D5: 2025 appliance (pre-release) | E5: System architecture design | F5: Design review | G5: Internal | H5: Alexander Peter (EchoMind Project Lead) | I5: Architecture reviewed against the offline RAG need | J5: Approved with minor corrections | K5: Deliverables Review DR-1.0 — MM-2025-05-01, Jira EMD-03 | L5: =SUMIF('Action log'!$B:$B,A5,'Action log'!$K:$K) | M5: =SUMIFS('Action log'!$K:$K,'Action log'!$B:$B,A5,'Action log'!$F:$F,"Closed*") | N5: =L5-M5 | O5: 2025 appliance
A6: DR-2025-02 | B6: 2025-05-18 | C6: P-2025-1 | D6: 2025 appliance (pre-release) | E6: Architecture alignment workshop | F6: Design review (meeting) | G6: Internal | H6: Alexander Peter (chair); Project Manager, Lead Architect, QA Lead | I6: Diagrams validated; concern about GPU memory allocation; QA asked for early prototype testing | J6: Draft accepted with minor updates; prototype fast-tracked for June | K6: Minutes MM-ECHO-2025-05 | L6: =SUMIF('Action log'!$B:$B,A6,'Action log'!$K:$K) | M6: =SUMIFS('Action log'!$K:$K,'Action log'!$B:$B,A6,'Action log'!$F:$F,"Closed*") | N6: =L6-M6 | O6: 2025 appliance
A7: DR-2025-03 | B7: 2025-05-22 | C7: P-2025-1 | D7: 2025 appliance (pre-release) | E7: Requirement validation | F7: Requirements review | G7: Internal | H7: AJACE PM / Quality team | I7: Requirements validated | J7: Approved | K7: Acceptance Criteria Review ACC-1.0 — MM-2025-05-02, Jira REQ-2025-05 | L7: =SUMIF('Action log'!$B:$B,A7,'Action log'!$K:$K) | M7: =SUMIFS('Action log'!$K:$K,'Action log'!$B:$B,A7,'Action log'!$F:$F,"Closed*") | N7: =L7-M7 | O7: 2025 appliance
A8: DR-2025-04 | B8: 2025-06-05 | C8: P-2025-1 | D8: 2025 appliance (pre-release) | E8: Deployment sprint planning | F8: Schedule review | G8: Internal | H8: AJACE PM team | I8: Deployment sprint scope and dates | J8: Scheduled | K8: Scheduling Review SCH-1.0 — MM-2025-06-01, Jira Sprint-2025-06 | L8: =SUMIF('Action log'!$B:$B,A8,'Action log'!$K:$K) | M8: =SUMIFS('Action log'!$K:$K,'Action log'!$B:$B,A8,'Action log'!$F:$F,"Closed*") | N8: =L8-M8 | O8: 2025 appliance
A9: DR-2025-05 | B9: 2025-07-10 | C9: P-2025-2 | D9: 2025 appliance (prototype) | E9: Prototype hardware | F9: Deliverable review | G9: Internal | H9: Alexander Peter (EchoMind Project Lead) | I9: Prototype hardware against the specification | J9: Approved | K9: Deliverables Review DR-1.0 — MM-2025-07-01, DocuSign SOW-2025-07 | L9: =SUMIF('Action log'!$B:$B,A9,'Action log'!$K:$K) | M9: =SUMIFS('Action log'!$K:$K,'Action log'!$B:$B,A9,'Action log'!$F:$F,"Closed*") | N9: =L9-M9 | O9: 2025 appliance
A10: DR-2025-06 | B10: 2025-07-12 | C10: P-2025-2 | D10: 2025 appliance (prototype) | E10: QA sprint planning | F10: Test planning review (meeting) | G10: Internal | H10: Alexander Peter (chair); QA Manager, Project Manager, Dev Lead | I10: QA backlog prioritised; transcription tests scheduled; defect triage twice a week | J10: QA sprint plan approved; defect triage from 2025-07-15 | K10: Minutes MM-ECHO-2025-07; SCH-1.0 MM-2025-07-02 | L10: =SUMIF('Action log'!$B:$B,A10,'Action log'!$K:$K) | M10: =SUMIFS('Action log'!$K:$K,'Action log'!$B:$B,A10,'Action log'!$F:$F,"Closed*") | N10: =L10-M10 | O10: 2025 appliance
A11: DR-2025-07 | B11: 2025-07-15 | C11: P-2025-2 | D11: 2025 appliance (prototype) | E11: Acceptance criteria mapping | F11: Acceptance criteria review | G11: Internal | H11: AJACE Quality / UAT team | I11: Acceptance criteria mapped to test cases | J11: Completed | K11: ACC-1.0 — MM-2025-07-03, test case TC-07 | L11: =SUMIF('Action log'!$B:$B,A11,'Action log'!$K:$K) | M11: =SUMIFS('Action log'!$K:$K,'Action log'!$B:$B,A11,'Action log'!$F:$F,"Closed*") | N11: =L11-M11 | O11: 2025 appliance
A12: DR-2025-08 | B12: 2025-08-03 | C12: P-2025-2 | D12: 2025 appliance (prototype) | E12: Technical documentation (draft v0.9) | F12: Document review | G12: Internal | H12: Alexander Peter (Project Lead); Antony Johan (Project Sponsor) | I12: Draft technical documentation reviewed | J12: Review logged; outcome not stated in the record | K12: ‘Deliverables formally logged and analysed’ record | L12: =SUMIF('Action log'!$B:$B,A12,'Action log'!$K:$K) | M12: =SUMIFS('Action log'!$K:$K,'Action log'!$B:$B,A12,'Action log'!$F:$F,"Closed*") | N12: =L12-M12 | O12: 2025 appliance
A13: DR-2025-09 | B13: 2025-08-05 | C13: P-2025-2 | D13: 2025 appliance | E13: Statement of work (requirements) | F13: Requirements review with the customer | G13: Client | H13: 2025 university pilot customer procurement office; AJACE | I13: Requirements: fully offline on-premises AI system; Pilot Program BYOA (application and consulting, onsite setup) | J13: SOW signed by both parties | K13: DocuSign envelope (ID in the controlled copy); ECH-QMS-010 | L13: =SUMIF('Action log'!$B:$B,A13,'Action log'!$K:$K) | M13: =SUMIFS('Action log'!$K:$K,'Action log'!$B:$B,A13,'Action log'!$F:$F,"Closed*") | N13: =L13-M13 | O13: 2025 appliance
A14: DR-2025-10 | B14: 2025-08-25 | C14: P-2025-2 | D14: 2025 appliance | E14: Final delivery milestones | F14: Schedule review | G14: Internal | H14: AJACE PM team | I14: Contract milestones checked | J14: Validated | K14: SCH-1.0 — MM-2025-08-01, contract milestone sheet | L14: =SUMIF('Action log'!$B:$B,A14,'Action log'!$K:$K) | M14: =SUMIFS('Action log'!$K:$K,'Action log'!$B:$B,A14,'Action log'!$F:$F,"Closed*") | N14: =L14-M14 | O14: 2025 appliance
A15: DR-2025-11 | B15: 2025-09-05 | C15: P-2025-3 | D15: 2025 appliance | E15: Design against SOW | F15: Design verification review | G15: Internal | H15: AJACE Quality / UAT team | I15: Design checked against the SOW | J15: Closed | K15: ACC-1.0 — MM-2025-09-02, DocuSign SOW-2025-09 | L15: =SUMIF('Action log'!$B:$B,A15,'Action log'!$K:$K) | M15: =SUMIFS('Action log'!$K:$K,'Action log'!$B:$B,A15,'Action log'!$F:$F,"Closed*") | N15: =L15-M15 | O15: 2025 appliance
A16: DR-2025-12 | B16: 2025-09-14 | C16: P-2025-3 | D16: 2025 appliance | E16: Provider performance | F16: Provider review (meeting) | G16: Internal | H16: Alexander Peter (chair); Procurement Lead, Project Manager, Operations Lead | I16: July batch on time, August batch late; one hardware defect returned | J16: Supplier satisfactory; extra QA checks at delivery | K16: Minutes MM-ECHO-2025-09 | L16: =SUMIF('Action log'!$B:$B,A16,'Action log'!$K:$K) | M16: =SUMIFS('Action log'!$K:$K,'Action log'!$B:$B,A16,'Action log'!$F:$F,"Closed*") | N16: =L16-M16 | O16: 2025 appliance
... A37: RV-2026-08 | B37: 2026-10-07 | C37: P-2026-5 | D37: v1.4.1 (public instance) | E37: Public instance access logs | F37: Log review for the ungated period | G37: Internal | H37: Richard Watson Stephen Amudha | I37: Ungated 68 days; 64 scanner probes; no data change outside engineering work | J37: External login check; record runtime changes | K37: records/capa/2026-10-07_NC-2026-009_access_log_review.md | L37: =SUMIF('Action log'!$B:$B,A37,'Action log'!$K:$K) | M37: =SUMIFS('Action log'!$K:$K,'Action log'!$B:$B,A37,'Action log'!$F:$F,"Closed*") | N37: =L37-M37 | O37: v1.4.1

Sheet Action log
A1: Action log — 2025 → 2026
A2: ‘Not evidenced’ = recorded as open in a 2025 minute with no later closure record. ‘Represents’ counts AC-04 as the 22 confirmed voice findings it stands for.
A4: Action ID | B4: From review | C4: Period | D4: Action | E4: Owner | F4: Status | G4: Due | H4: Closed on | I4: Closure evidence | J4: Ticket / link | K4: Represents | L4: Version
A5: DA-2025-01 | B5: DR-2025-02 | C5: P-2025-1 | D5: Update architecture diagrams with GPU allocation | E5: Lead Architect | F5: Not evidenced | G5: 2025-05-25 | I5: Recorded open in MM-ECHO-2025-05; no later closure record (superseded by the 2026 platform) | K5: 1 | L5: 2025 appliance
A6: DA-2025-02 | B6: DR-2025-02 | C6: P-2025-1 | D6: Prepare prototype test plan | E6: QA Lead | F6: Closed | G6: 2025-06-05 | H6: 2025-07-12 | I6: QA sprint plan approved in MM-ECHO-2025-07 | J6: DR-2025-06 | K6: 1 | L6: 2025 appliance
A7: DA-2025-03 | B7: DR-2025-06 | C7: P-2025-2 | D7: Finalise QA sprint board | E7: QA Manager | F7: Closed | G7: 2025-07-14 | H7: 2025-07-14 | I7: Recorded closed in MM-ECHO-2025-07 | K7: 1 | L7: 2025 appliance
A8: DA-2025-04 | B8: DR-2025-06 | C8: P-2025-2 | D8: Confirm test environment set-up | E8: Dev Lead | F8: Not evidenced | G8: 2025-07-16 | I8: Recorded open in MM-ECHO-2025-07; regression run on 2025-09-05 used the test environment | K8: 1 | L8: 2025 appliance
A9: DA-2025-05 | B9: DR-2025-12 | C9: P-2025-3 | D9: Issue supplier performance scorecard | E9: Procurement Lead | F9: Closed | G9: 2025-09-20 | H9: 2025-10-10 | I9: Provider scorecard Q3-2025 reviewed 2025-10-10 (AFR row 14); lessons log #6, CR-2025-03 | K9: 1 | L9: 2025 appliance
A10: DA-2025-06 | B10: DR-2025-12 | C10: P-2025-3 | D10: Document the new QA delivery check process | E10: Operations Lead | F10: Closed | G10: 2025-09-25 | H10: 2025-10 | I10: Pre-acceptance QA checklist for vendors (lessons log #17, CR-2025-03) | K10: 1 | L10: 2025 appliance
A11: DA-2025-07 | B11: DR-2025-01 | C11: P-2025-1 | D11: Cross-check hardware specification against project needs before approval | E11: Alexander Peter | F11: Closed | G11: 2025-05-15 | H11: 2025-05-15 | I11: Deliverables Review DR-1.0, risks and actions | K11: 1 | L11: 2025 appliance
A12: DA-2025-08 | B12: DR-2025-09 | C12: P-2025-2 | D12: Validation session with stakeholders on SOW requirement mismatches | E12: AJACE PM team | F12: Closed | G12: 2025-07 | H12: 2025-07 | I12: DR-1.0 risks and actions; SOW signed 2025-08-05 | K12: 1 | L12: 2025 appliance
A13: DA-2025-09 | B13: DR-2025-13 | C13: P-2025-3 | D13: Mandatory QA checklist before release sign-off | E13: QA | F13: Closed | G13: 2025-09 | H13: 2025-09 | I13: DR-1.0 risks and actions | K13: 1 | L13: 2025 appliance
A14: DA-2025-10 | B14: DR-2025-10 | C14: P-2025-2 | D14: Weekly milestone checks; backlog grooming; milestones tracked in Jira | E14: AJACE PM team | F14: Closed | G14: 2025-09 | H14: 2025-10-10 | I14: SCH-1.0 risks and actions; AFR row 12 verified 2025-10-10 | K14: 1 | L14: 2025 appliance
A15: DA-2025-11 | B15: DR-2025-07 | C15: P-2025-2 | D15: Standard acceptance-criteria template; joint requirement reviews; SOW sign-off session | E15: AJACE Quality / UAT team | F15: Closed | G15: 2025-09 | H15: 2025-10-10 | I15: ACC-1.0 risks and actions; AFR row 13 verified in sprint review 2025-10-10 | K15: 1 | L15: 2025 appliance
A16: DA-2025-12 | B16: DR-2025-14 | C16: P-2025-3 | D16: Deliverables review record with formal logging and reviewer sign-off | E16: AJACE Quality team | F16: Closed | G16: 2025-10-08 | H16: 2025-10-08 | I16: AFR row 11 — verified by QA 2025-10-08 | K16: 1 | L16: 2025 appliance
A17: DA-2025-13 | B17: DR-2025-14 | C17: P-2025-3 | D17: Test failure → defect → regression documentation (DEF-2025-01, REG-2025-01) | E17: QA | F17: Closed | G17: 2025-10-10 | H17: 2025-10-10 | I17: AFR row 15 — regression run 2025-09-05 confirmed QA-FAIL-01 resolved | K17: 1 | L17: 2025 appliance
A18: DA-2025-14 | B18: DR-2025-14 | C18: P-2025-3 | D18: Lessons-learnt logbook adopted | E18: PMO | F18: Closed | G18: 2025-10-11 | H18: 2025-10-11 | I18: AFR row 16 — reviewed in internal audit 2025-10-11 | K18: 1 | L18: 2025 appliance
A19: DA-2025-15 | B19: DR-2025-15 | C19: P-2025-3 | D19: Record and monitor non-functional requirements (finding #6) | E19: Richard Watson Stephen Amudha | F19: Closed | G19: 2026-10-07 | H19: 2026-10-07 | I19: REG-09; EM26-17 (targets approved AR-2026-001) | J19: #49 | K19: 1 | L19: 2025 appliance
A20: DA-2025-16 | B20: DR-2025-15 | C20: P-2025-3 | D20: Log actions from review feedback of deliverables (finding #7) | E20: Richard Watson Stephen Amudha | F20: Closed | G20: 2026-10-07 | H20: 2026-10-07 | I20: REG-10; EM26-18 | K20: 1 | L20: 2025 appliance
A21: AC-20 | B21: CR-2026-01 | C21: P-2026-1 | D21: Buy the first DGX Spark and port the 2025 code to it (ARM64) | E21: EchoMind team | F21: Closed | G21: 2026-02 | H21: 2026-02 | I21: 4b90b36, c751d79 (2026-02-05) — 2025 code running on the DGX Spark | J21: — | K21: 1 | L21: v1.0.0
A22: AC-21 | B22: CR-2026-02 | C22: P-2026-2 | D22: Personal AI assistant: financial-assistant behaviour, conversation memory, personas | E22: Richard Watson Stephen Amudha | F22: Closed | G22: 2026-04 | H22: 2026-04 | I22: 95d3512, e59fd55 (2026-03-08); 518fb8e (2026-04-08); c6b834d (2026-06-27) | J22: — | K22: 1 | L22: v1.0.0
A23: AC-22 | B23: CR-2026-02 | C23: P-2026-2 | D23: DoD FMR knowledge base: try BookRAG and PageIndex; adopt hierarchical section → chunk retrieval with table-of-contents routing and regulation-tuned query classification | E23: Richard Watson Stephen Amudha | F23: Closed | G23: 2026-03 | H23: 2026-03 | I23: 31f1205, 045b1b1 (03-03); 18715c7, cfe3360 (03-05); 5057a30 (03-06). BookRAG 23ac2f9 (03-07) measured 43/52 vs 50/52 and was switched off (2decb99, 07-30); PageIndex evaluated, not adopted | J23: — | K23: 1 | L23: v1.0.0
A24: AC-23 | B24: CR-2026-03 | C24: P-2026-2 | D24: Replace the Unmute stack with NVIDIA PersonaPlex | E24: Richard Watson Stephen Amudha | F24: Closed | G24: 2026-03 | H24: 2026-03 | I24: Trial compared in the QASC 2026 paper; trial code not kept | J24: — | K24: 1 | L24: v1.0.0
A25: AC-24 | B25: CR-2026-04 | C25: P-2026-2 | D25: Build our own dual-loop conversation architecture grounded in the customer's knowledge base | E25: Richard Watson Stephen Amudha | F25: Closed | G25: 2026-04 | H25: 2026-04 | I25: ddc0aa3, d89aeda (04-08); fbbadd0 (05-28); 5ce8bbe, cbc57d1 (08-07) — 636 ms median first audio vs 866 ms single loop | J25: — | K25: 1 | L25: v1.1.0
A26: AC-25 | B26: CR-2026-05 | C26: P-2026-2 | D26: Hotspot: unit raises a Wi-Fi hotspot at every boot and serves a landing page that opens the applications | E26: Alexander Peter | F26: Closed | G26: 2026-04 | H26: 2026-04 | I26: Built on the deployment unit; offline preparation 0818cdc (2026-04-10) | J26: — | K26: 1 | L26: v1.1.0
A27: AC-26 | B27: CR-2026-05 | C27: P-2026-2 | D27: Bring the hotspot configuration under version control and add it to the deployment guide | E27: Alexander Peter | F27: Open | G27: 2026-10-31 | I27: — | J27: — | K27: 1 | L27: v1.1.0
A28: AC-27 | B28: CR-2026-06 | C28: P-2026-2 | D28: Replace Whisper with Nemotron streaming speech recognition for live transcription | E28: Richard Watson Stephen Amudha | F28: Closed | G28: 2026-04-08 | H28: 2026-04-08 | I28: d89aeda, 172b94c, ddc0aa3 | J28: — | K28: 1 | L28: v1.1.0
A29: AC-28 | B29: CR-2026-06 | C29: P-2026-2 | D29: Accurate final transcript with Parakeet-TDT and automatic fallback to the streaming model | E29: Richard Watson Stephen Amudha | F29: Closed | G29: 2026-06-26 | H29: 2026-06-26 | I29: b6a70d8, 3a6b1f9 — fixes 'DoD FMR' → 'DODFMA' | J29: — | K29: 1 | L29: v1.1.0
A30: AC-29 | B30: CR-2026-06 | C30: P-2026-2 | D30: Move chat generation from Ollama to TensorRT-LLM for speed | E30: Richard Watson Stephen Amudha | F30: Closed | G30: 2026-07-29 | H30: 2026-07-29 | I30: 06e788a (03-20) integration; 80375c6 (07-29) Qwen3-30B-A3B NVFP4 on TensorRT-LLM; Ollama kept for embeddings and rollback | J30: — | K30: 1 | L30: v1.1.0
A31: AC-30 | B31: CR-2026-07 | C31: P-2026-3 | D31: Silent Assistant: runs with the live transcript; an assistant and an agent check the content continuously and surface data and pointers on screen without replying | E31: Richard Watson Stephen Amudha | F31: Closed | G31: 2026-05-11 | H31: 2026-05-11 | I31: ec9b180 (2026-05-11) | J31: — | K31: 1 | L31: v1.1.0
A32: AC-31 | B32: CR-2026-07 | C32: P-2026-3 | D32: Law rule pack, always-surface mode, namespace awareness; sentence-level checks with quoted proof | E32: Richard Watson Stephen Amudha | F32: Closed | G32: 2026-08-16 | H32: 2026-08-16 | I32: f75121b (06-27), 7f2658a (08-16) | J32: — | K32: 1 | L32: v1.1.0
A33: AC-32 | B33: CR-2026-08 | C33: P-2026-3 | D33: Select a diarisation model by trial; build Boardroom (group discussion, speaker-separated transcript, report) | E33: Richard Watson Stephen Amudha | F33: Closed | G33: 2026-05-27 | H33: 2026-05-27 | I33: f540976 (05-14), cf463aa (05-19), e1a337b (05-27); VibeVoice-ASR adopted (REG-02 M-06) | J33: — | K33: 1 | L33: v1.2.0
A34: AC-33 | B34: CR-2026-08 | C34: P-2026-3 | D34: Harden Boardroom: report salvage when the model output is truncated | E34: Richard Watson Stephen Amudha | F34: Closed | G34: 2026-09-04 | H34: 2026-09-04 | I34: b08cf25 (06-18), 724fb98 (09-04) | J34: — | K34: 1 | L34: v1.2.0
A35: AC-34 | B35: CR-2026-09 | C35: P-2026-3 | D35: Evaluate image-generation and document models; build Document Studio with PDF and PPTX export, on-device images, with and without a template | E35: Richard Watson Stephen Amudha | F35: Closed | G35: 2026-06-27 | H35: 2026-06-27 | I35: 2d23f40 (06-20), 66356f9 (06-27); SDXL-Turbo on device (REG-02) | J35: — | K35: 1 | L35: v1.2.0
A36: AC-35 | B36: SR-2026-01 | C36: P-2026-3 | D36: Allow-list audio formats and contain upload paths (Boardroom) | E36: Richard Watson Stephen Amudha | F36: Closed | G36: 2026-06-18 | H36: 2026-06-18 | I36: b08cf25 | J36: — | K36: 1 | L36: v1.2.0
A37: AC-36 | B37: SR-2026-01 | C37: P-2026-3 | D37: Escape all LLM and transcript text in PDF export | E37: Richard Watson Stephen Amudha | F37: Closed | G37: 2026-06-18 | H37: 2026-06-18 | I37: b08cf25 | J37: — | K37: 1 | L37: v1.2.0
A38: AC-37 | B38: SR-2026-01 | C38: P-2026-3 | D38: Prompt-injection guards and fenced untrusted context in chat, Boardroom and voice | E38: Richard Watson Stephen Amudha | F38: Closed | G38: 2026-06-18 | H38: 2026-06-18 | I38: b08cf25; unit tests run by CI since 2026-10-07 | J38: — | K38: 1 | L38: v1.2.0
A39: AC-38 | B39: SR-2026-01 | C39: P-2026-3 | D39: Stop logging full prompts at INFO; server-generated transcript session IDs | E39: Richard Watson Stephen Amudha | F39: Closed | G39: 2026-06-18 | H39: 2026-06-18 | I39: b08cf25 | J39: — | K39: 1 | L39: v1.2.0
... A41: AC-02 | B41: RV-2026-01 | C41: P-2026-4 | D41: Fix five retrieval defects found by the golden suite | E41: Richard Watson Stephen Amudha | F41: Closed | G41: 2026-07-29 | H41: 2026-07-29 | I41: ebd232f — suite restored to 49/52 | J41: — | K41: 1 | L41: v1.3.0
A42: AC-03 | B42: RV-2026-02 | C42: P-2026-4 | D42: Record contradicting findings verbatim; correct the claims in the next paper version | E42: Richard Watson Stephen Amudha | F42: Open (recording done) | G42: Next version | I42: SUMMARY.json | J42: #19, #27 | K42: 1 | L42: v1.3.0
...

Sheet Summary
A1: Summary — live formulas
A4: Group | B4: Reviews | C4: Actions raised | D4: Actions closed
A5: 2025 reviews | B5: =COUNTIF('Review log'!$A:$A,"DR-2025*") | C5: =SUMPRODUCT((LEFT('Action log'!$B$5:$B$58,7)="DR-2025")*'Action log'!$K$5:$K$58) | D5: =SUMPRODUCT((LEFT('Action log'!$B$5:$B$58,7)="DR-2025")*(LEFT('Action log'!$F$5:$F$58,6)="Closed")*'Action log'!$K$5:$K$58)
A6: 2026 client and design reviews | B6: =COUNTIF('Review log'!$A:$A,"CR-2026*") | C6: =SUMPRODUCT((LEFT('Action log'!$B$5:$B$58,7)="CR-2026")*'Action log'!$K$5:$K$58) | D6: =SUMPRODUCT((LEFT('Action log'!$B$5:$B$58,7)="CR-2026")*(LEFT('Action log'!$F$5:$F$58,6)="Closed")*'Action log'!$K$5:$K$58)
A7: 2026 code audit | B7: =COUNTIF('Review log'!$A:$A,"SR-2026*") | C7: =SUMPRODUCT((LEFT('Action log'!$B$5:$B$58,7)="SR-2026")*'Action log'!$K$5:$K$58) | D7: =SUMPRODUCT((LEFT('Action log'!$B$5:$B$58,7)="SR-2026")*(LEFT('Action log'!$F$5:$F$58,6)="Closed")*'Action log'!$K$5:$K$58)
A8: 2026 engineering and quality reviews | B8: =COUNTIF('Review log'!$A:$A,"RV-2026*") | C8: =SUMPRODUCT((LEFT('Action log'!$B$5:$B$58,7)="RV-2026")*'Action log'!$K$5:$K$58) | D8: =SUMPRODUCT((LEFT('Action log'!$B$5:$B$58,7)="RV-2026")*(LEFT('Action log'!$F$5:$F$58,6)="Closed")*'Action log'!$K$5:$K$58)
A9: Total | B9: =SUM(B5:B8) | C9: =SUM(C5:C8) | D9: =SUM(D5:D8)
A12: Review source | B12: Reviews
A13: Client | B13: =COUNTIF('Review log'!$G:$G,"Client")
A14: Internal | B14: =COUNTIF('Review log'!$G:$G,"Internal")
A15: Internal audit | B15: =COUNTIF('Review log'!$G:$G,"Internal audit")
A16: External audit | B16: =COUNTIF('Review log'!$G:$G,"External audit")
